Workbook
Name ScenarioSelected: '01_Control'!$B$2
Name VolumeMethod: '01_Control'!$B$7
Name AssumptionTable: '02_Assumptions'!$A$1:$M$200
Name VOL_001_Derived: '05_Payroll_Activity'!$C$2:$G$2
Name AnnualSuccessfulTransactions: '05_Payroll_Activity'!$C$3:$G$3

Sheet 00_Read_Me
A1: Payroll Starter Financial Model
A2: Level 1 Controlled Placeholder Model
A4: Warning | B4: This workbook uses provisional management candidates and controlled placeholders. It is not an approved budget, forecast, provider quote, institutional commitment, contract, regulatory filing, investment representation, or factual operating result.
A5: Revenue warning | B5: Stakeholder revenue figures include internal transfers and are not additive. Consolidated External Revenue counts external inflows once.
A7: Canonical sources
A8: provisionalInputs | B8: docs/economics/offerings/rural-bank-payroll-starter/provisional-input-register-level-1.md
A9: level1Model | B9: docs/economics/offerings/rural-bank-payroll-starter/offering-economics-level-1.md
A10: summary | B10: docs/economics/offerings/rural-bank-payroll-starter/five-year-revenue-projection-summary.md
A11: specification | B11: docs/economics/offerings/rural-bank-payroll-starter/spreadsheet-financial-model.md
A13: Slice 2 sheets
A14: 00_Read_Me
A15: 01_Control
A16: 02_Assumptions
A17: 03_Assumption_Map
A18: 04_Adoption
A19: 05_Payroll_Activity
A20: 21_Checks

Sheet 01_Control
A1: Control | B1: Default | C1: Allowed values | D1: Notes
A2: Selected scenario | B2: Base | C2: Conservative, Base, Accelerated | D2: Data validation to be added in workbook implementation.
A3: Model start year | B3: Year 1 | C3: Year 1 | D3: Fixed for Level 1.
A4: Projection horizon | B4: 5 | C4: 5 | D4: Fixed for Level 1.
A5: Include optional SMS | B5: No | C5: Yes, No | D5: Core Payroll remains primary.
A6: Cost view | B6: Incremental Payroll | C6: Incremental Payroll, Full-Cost Stress Test | D6: Shared allocation deferred.
A7: Volume method | B7: Component-derived | C7: Component-derived | D7: Aggregate volume disabled until authorized.
A8: Discount rate | B8: Blocked | C8: Blocked | D8: Future FIN-001 needed.
A9: Model version | B9: Level 1 | C9: Level 1 | D9: Must match canonical documents.

Sheet 02_Assumptions
A1: Provisional Input ID | B1: Assumption ID or source | C1: Description | D1: Input Type | E1: Year | F1: Conservative | G1: Base | H1: Accelerated | I1: Selected Scenario Value | J1: Current Status | K1: Evidence Status | L1: Input Classification | M1: Source
A2: PI-L1-001 | B2: ADP-001 | C2: Newly onboarded banks during year | D2: yearVector | E2: Year 1 | F2: 2 | G2: 5 | H2: 10 | I2: =CHOOSE(MATCH('01_Control'!$B$2,$F$1:$H$1,0),F2,G2,H2) -> 5 | J2: Provisional | K2: Internal management candidate; not evidence-supported | L2: Controlled placeholder | M2: docs/economics/offerings/rural-bank-payroll-starter/provisional-input-register-level-1.md
A3: PI-L1-001 | B3: ADP-001 | C3: Newly onboarded banks during year | D3: yearVector | E3: Year 2 | F3: 3 | G3: 7 | H3: 12 | I3: =CHOOSE(MATCH('01_Control'!$B$2,$F$1:$H$1,0),F3,G3,H3) -> 7 | J3: Provisional | K3: Internal management candidate; not evidence-supported | L3: Controlled placeholder | M3: docs/economics/offerings/rural-bank-payroll-starter/provisional-input-register-level-1.md
A4: PI-L1-001 | B4: ADP-001 | C4: Newly onboarded banks during year | D4: yearVector | E4: Year 3 | F4: 4 | G4: 8 | H4: 15 | I4: =CHOOSE(MATCH('01_Control'!$B$2,$F$1:$H$1,0),F4,G4,H4) -> 8 | J4: Provisional | K4: Internal management candidate; not evidence-supported | L4: Controlled placeholder | M4: docs/economics/offerings/rural-bank-payroll-starter/provisional-input-register-level-1.md
A5: PI-L1-001 | B5: ADP-001 | C5: Newly onboarded banks during year | D5: yearVector | E5: Year 4 | F5: 4 | G5: 10 | H5: 18 | I5: =CHOOSE(MATCH('01_Control'!$B$2,$F$1:$H$1,0),F5,G5,H5) -> 10 | J5: Provisional | K5: Internal management candidate; not evidence-supported | L5: Controlled placeholder | M5: docs/economics/offerings/rural-bank-payroll-starter/provisional-input-register-level-1.md
A6: PI-L1-001 | B6: ADP-001 | C6: Newly onboarded banks during year | D6: yearVector | E6: Year 5 | F6: 5 | G6: 10 | H6: 20 | I6: =CHOOSE(MATCH('01_Control'!$B$2,$F$1:$H$1,0),F6,G6,H6) -> 10 | J6: Provisional | K6: Internal management candidate; not evidence-supported | L6: Controlled placeholder | M6: docs/economics/offerings/rural-bank-payroll-starter/provisional-input-register-level-1.md
A7: PI-L1-002 | B7: ADP-002 | C7: Active banks during year | D7: yearVector | E7: Year 1 | F7: 1 | G7: 3 | H7: 7 | I7: =CHOOSE(MATCH('01_Control'!$B$2,$F$1:$H$1,0),F7,G7,H7) -> 3 | J7: Provisional | K7: Internal management candidate; not evidence-supported | L7: Controlled placeholder | M7: docs/economics/offerings/rural-bank-payroll-starter/provisional-input-register-level-1.md
A8: PI-L1-002 | B8: ADP-002 | C8: Active banks during year | D8: yearVector | E8: Year 2 | F8: 3 | G8: 8 | H8: 16 | I8: =CHOOSE(MATCH('01_Control'!$B$2,$F$1:$H$1,0),F8,G8,H8) -> 8 | J8: Provisional | K8: Internal management candidate; not evidence-supported | L8: Controlled placeholder | M8: docs/economics/offerings/rural-bank-payroll-starter/provisional-input-register-level-1.md
A9: PI-L1-002 | B9: ADP-002 | C9: Active banks during year | D9: yearVector | E9: Year 3 | F9: 6 | G9: 14 | H9: 28 | I9: =CHOOSE(MATCH('01_Control'!$B$2,$F$1:$H$1,0),F9,G9,H9) -> 14 | J9: Provisional | K9: Internal management candidate; not evidence-supported | L9: Controlled placeholder | M9: docs/economics/offerings/rural-bank-payroll-starter/provisional-input-register-level-1.md
A10: PI-L1-002 | B10: ADP-002 | C10: Active banks during year | D10: yearVector | E10: Year 4 | F10: 9 | G10: 22 | H10: 42 | I10: =CHOOSE(MATCH('01_Control'!$B$2,$F$1:$H$1,0),F10,G10,H10) -> 22 | J10: Provisional | K10: Internal management candidate; not evidence-supported | L10: Controlled placeholder | M10: docs/economics/offerings/rural-bank-payroll-starter/provisional-input-register-level-1.md
A11: PI-L1-002 | B11: ADP-002 | C11: Active banks during year | D11: yearVector | E11: Year 5 | F11: 12 | G11: 32 | H11: 60 | I11: =CHOOSE(MATCH('01_Control'!$B$2,$F$1:$H$1,0),F11,G11,H11) -> 32 | J11: Provisional | K11: Internal management candidate; not evidence-supported | L11: Controlled placeholder | M11: docs/economics/offerings/rural-bank-payroll-starter/provisional-input-register-level-1.md
A12: PI-L1-003 | B12: ADP-003 | C12: Weighted average active months per active bank | D12: yearVector | E12: Year 1 | F12: 4 | G12: 5 | H12: 6 | I12: =CHOOSE(MATCH('01_Control'!$B$2,$F$1:$H$1,0),F12,G12,H12) -> 5 | J12: Provisional | K12: Internal management candidate; not evidence-supported | L12: Controlled placeholder | M12: docs/economics/offerings/rural-bank-payroll-starter/provisional-input-register-level-1.md
A13: PI-L1-003 | B13: ADP-003 | C13: Weighted average active months per active bank | D13: yearVector | E13: Year 2 | F13: 6 | G13: 7 | H13: 8 | I13: =CHOOSE(MATCH('01_Control'!$B$2,$F$1:$H$1,0),F13,G13,H13) -> 7 | J13: Provisional | K13: Internal management candidate; not evidence-supported | L13: Controlled placeholder | M13: docs/economics/offerings/rural-bank-payroll-starter/provisional-input-register-level-1.md
... A20: PI-L1-007 | B20: VOL-002 | C20: Successful completion rate | D20: scalar | E20: All | F20: 0.92 | G20: 0.96 | H20: 0.98 | I20: =CHOOSE(MATCH('01_Control'!$B$2,$F$1:$H$1,0),F20,G20,H20) -> 0.96 | J20: Provisional | K20: Internal management candidate; not evidence-supported | L20: Controlled placeholder | M20: docs/economics/offerings/rural-bank-payroll-starter/provisional-input-register-level-1.md
A21: PI-L1-008 | B21: VOL-001 | C21: Successful payroll transactions per active bank per month | D21: derived | E21: All | F21: CUS-001 x CUS-002 x CUS-003 x VOL-002 | G21: CUS-001 x CUS-002 x CUS-003 x VOL-002 | H21: CUS-001 x CUS-002 x CUS-003 x VOL-002 | I21: =CHOOSE(MATCH('01_Control'!$B$2,$F$1:$H$1,0),F21,G21,H21) -> CUS-001 x CUS-002 x CUS-003 x VOL-002 | J21: Derived | K21: Calculated from component assumptions | L21: Derived input | M21: docs/economics/offerings/rural-bank-payroll-starter/provisional-input-register-level-1.md
A22: PI-L1-009 | B22: EMP-001 | C22: Employer onboarding fee | D22: scalar | E22: All | F22: 1500 | G22: 3000 | H22: 5000 | I22: =CHOOSE(MATCH('01_Control'!$B$2,$F$1:$H$1,0),F22,G22,H22) -> 3000 | J22: Provisional | K22: Internal management candidate; not evidence-supported | L22: Controlled placeholder | M22: docs/economics/offerings/rural-bank-payroll-starter/provisional-input-register-level-1.md
A23: PI-L1-010 | B23: EMP-002 | C23: Employer monthly payroll-service fee | D23: scalar | E23: All | F23: 300 | G23: 750 | H23: 1250 | I23: =CHOOSE(MATCH('01_Control'!$B$2,$F$1:$H$1,0),F23,G23,H23) -> 750 | J23: Provisional | K23: Internal management candidate; not evidence-supported | L23: Controlled placeholder | M23: docs/economics/offerings/rural-bank-payroll-starter/provisional-input-register-level-1.md
A24: PI-L1-011 | B24: LIC-004 | C24: Rural-bank platform activation fee | D24: scalar | E24: All | F24: 50000 | G24: 50000 | H24: 50000 | I24: =CHOOSE(MATCH('01_Control'!$B$2,$F$1:$H$1,0),F24,G24,H24) -> 50000 | J24: Provisional | K24: Internal management candidate; not evidence-supported | L24: Controlled placeholder | M24: docs/economics/offerings/rural-bank-payroll-starter/provisional-input-register-level-1.md
A25: PI-L1-012 | B25: LIC-005 | C25: Annual platform subscription | D25: scalar | E25: All | F25: 60000 | G25: 60000 | H25: 60000 | I25: =CHOOSE(MATCH('01_Control'!$B$2,$F$1:$H$1,0),F25,G25,H25) -> 60000 | J25: Provisional | K25: Internal management candidate; not evidence-supported | L25: Controlled placeholder | M25: docs/economics/offerings/rural-bank-payroll-starter/provisional-input-register-level-1.md
A26: PI-L1-013 | B26: PRC-001 | C26: Fee per successful recipient disbursement | D26: scalar | E26: All | F26: 1 | G26: 1.5 | H26: 2 | I26: =CHOOSE(MATCH('01_Control'!$B$2,$F$1:$H$1,0),F26,G26,H26) -> 1.5 | J26: Provisional | K26: Internal management candidate; not evidence-supported | L26: Controlled placeholder | M26: docs/economics/offerings/rural-bank-payroll-starter/provisional-input-register-level-1.md
A27: PI-L1-014 | B27: RB-001 | C27: Rural-bank retained amount per successful recipient disbursement | D27: scalar | E27: All | F27: 0.4 | G27: 0.5 | H27: 0.6 | I27: =CHOOSE(MATCH('01_Control'!$B$2,$F$1:$H$1,0),F27,G27,H27) -> 0.5 | J27: Provisional | K27: Internal management candidate; not evidence-supported | L27: Controlled placeholder | M27: docs/economics/offerings/rural-bank-payroll-starter/provisional-input-register-level-1.md
A28: PI-L1-015 | B28: Decision 0003 | C28: EMP-001 split | D28: decision | E28: All | F28: ruralBank 40% / odti 60% | G28: ruralBank 40% / odti 60% | H28: ruralBank 40% / odti 60% | I28: =CHOOSE(MATCH('01_Control'!$B$2,$F$1:$H$1,0),F28,G28,H28) -> ruralBank 40% / odti 60% | J28: Provisional | K28: Internal management candidate; not evidence-supported | L28: Decision-backed provisional input | M28: docs/decisions/0003-payroll-starter-economic-treatment.md
A29: PI-L1-016 | B29: Decision 0003 | C29: EMP-002 split | D29: decision | E29: All | F29: ruralBank 60% / odti 40% | G29: ruralBank 60% / odti 40% | H29: ruralBank 60% / odti 40% | I29: =CHOOSE(MATCH('01_Control'!$B$2,$F$1:$H$1,0),F29,G29,H29) -> ruralBank 60% / odti 40% | J29: Provisional | K29: Internal management candidate; not evidence-supported | L29: Decision-backed provisional input | M29: docs/decisions/0003-payroll-starter-economic-treatment.md
A30: PI-L1-017 | B30: ODTI-001 | C30: Payroll-specific ODTI support cost per active bank-month | D30: scalar | E30: All | F30: 3000 | G30: 2500 | H30: 2000 | I30: =CHOOSE(MATCH('01_Control'!$B$2,$F$1:$H$1,0),F30,G30,H30) -> 2500 | J30: Provisional | K30: Internal management candidate; not evidence-supported | L30: Controlled placeholder | M30: docs/economics/offerings/rural-bank-payroll-starter/provisional-input-register-level-1.md
A31: PI-L1-018 | B31: ODTI-002 | C31: Payroll-specific ODTI implementation cost per newly onboarded bank | D31: scalar | E31: All | F31: 20000 | G31: 15000 | H31: 12000 | I31: =CHOOSE(MATCH('01_Control'!$B$2,$F$1:$H$1,0),F31,G31,H31) -> 15000 | J31: Provisional | K31: Internal management candidate; not evidence-supported | L31: Controlled placeholder | M31: docs/economics/offerings/rural-bank-payroll-starter/provisional-input-register-level-1.md
A32: PI-L1-019 | B32: OPS-001 | C32: DevOps setup fee per bank deployment | D32: scalar | E32: All | F32: 50000 | G32: 50000 | H32: 50000 | I32: =CHOOSE(MATCH('01_Control'!$B$2,$F$1:$H$1,0),F32,G32,H32) -> 50000 | J32: Provisional | K32: Internal management candidate; not evidence-supported | L32: Controlled placeholder | M32: docs/economics/offerings/rural-bank-payroll-starter/provisional-input-register-level-1.md
A33: PI-L1-020 | B33: OPS-002 | C33: DevOps monthly managed operations fee per active bank-month | D33: scalar | E33: All | F33: 10000 | G33: 10000 | H33: 10000 | I33: =CHOOSE(MATCH('01_Control'!$B$2,$F$1:$H$1,0),F33,G33,H33) -> 10000 | J33: Provisional | K33: Internal management candidate; not evidence-supported | L33: Controlled placeholder | M33: docs/economics/offerings/rural-bank-payroll-starter/provisional-input-register-level-1.md
A34: PI-L1-021 | B34: OPS-003 | C34: DevOps direct recurring cost per active bank-month | D34: scalar | E34: All | F34: 8000 | G34: 6000 | H34: 5000 | I34: =CHOOSE(MATCH('01_Control'!$B$2,$F$1:$H$1,0),F34,G34,H34) -> 6000 | J34: Provisional | K34: Internal management candidate; not evidence-supported | L34: Controlled placeholder | M34: docs/economics/offerings/rural-bank-payroll-starter/provisional-input-register-level-1.md
A35: PI-L1-022 | B35: CLD-001 | C35: Public-cloud cost per active bank-month | D35: scalar | E35: All | F35: 4000 | G35: 3000 | H35: 2500 | I35: =CHOOSE(MATCH('01_Control'!$B$2,$F$1:$H$1,0),F35,G35,H35) -> 3000 | J35: Provisional | K35: Internal management candidate; not evidence-supported | L35: Controlled placeholder | M35: docs/economics/offerings/rural-bank-payroll-starter/provisional-input-register-level-1.md
A36: PI-L1-023 | B36: RISK-002 | C36: Non-collection rate on employer commercial fees | D36: scalar | E36: All | F36: 0.05 | G36: 0.02 | H36: 0.01 | I36: =CHOOSE(MATCH('01_Control'!$B$2,$F$1:$H$1,0),F36,G36,H36) -> 0.02 | J36: Provisional | K36: Internal management candidate; not evidence-supported | L36: Controlled placeholder | M36: docs/economics/offerings/rural-bank-payroll-starter/provisional-input-register-level-1.md
A37: PI-L1-024 | B37: ATT-001 | C37: SMS attachment rate | D37: scalar | E37: All | F37: 0.25 | G37: 0.5 | H37: 0.7 | I37: =CHOOSE(MATCH('01_Control'!$B$2,$F$1:$H$1,0),F37,G37,H37) -> 0.5 | J37: Provisional | K37: Internal management candidate; not evidence-supported | L37: Controlled placeholder | M37: docs/economics/offerings/rural-bank-payroll-starter/provisional-input-register-level-1.md
A38: PI-L1-025 | B38: VAS-001 | C38: Customer-facing SMS price | D38: scalar | E38: All | F38: 1 | G38: 1 | H38: 1 | I38: =CHOOSE(MATCH('01_Control'!$B$2,$F$1:$H$1,0),F38,G38,H38) -> 1 | J38: Provisional | K38: Internal management candidate; not evidence-supported | L38: Controlled placeholder | M38: docs/economics/offerings/rural-bank-payroll-starter/provisional-input-register-level-1.md
A39: PI-L1-026 | B39: CST-001 | C39: SMS wholesale provider price | D39: scalar | E39: All | F39: 0.7 | G39: 0.5 | H39: 0.4 | I39: =CHOOSE(MATCH('01_Control'!$B$2,$F$1:$H$1,0),F39,G39,H39) -> 0.5 | J39: Provisional | K39: Internal management candidate; not evidence-supported | L39: Controlled placeholder | M39: docs/economics/offerings/rural-bank-payroll-starter/provisional-input-register-level-1.md
A40: PI-L1-027 | B40: SMS-001 | C40: SMS delivery success rate | D40: scalar | E40: All | F40: 0.9 | G40: 0.95 | H40: 0.97 | I40: =CHOOSE(MATCH('01_Control'!$B$2,$F$1:$H$1,0),F40,G40,H40) -> 0.95 | J40: Provisional | K40: Internal management candidate; not evidence-supported | L40: Controlled placeholder | M40: docs/economics/offerings/rural-bank-payroll-starter/provisional-input-register-level-1.md
A41: PI-L1-028 | B41: SMS-003 | C41: Failed-message treatment | D41: text | E41: All | F41: Delivered-only billing; failed attempts excluded | G41: Delivered-only billing; failed attempts excluded | H41: Delivered-only billing; failed attempts excluded | I41: =CHOOSE(MATCH('01_Control'!$B$2,$F$1:$H$1,0),F41,G41,H41) -> Delivered-only billing; failed attempts excluded | J41: Provisional | K41: Internal management candidate; not evidence-supported | L41: Governed policy input | M41: docs/economics/offerings/rural-bank-payroll-starter/provisional-input-register-level-1.md
A42: PI-L1-029 | B42: SMS-004 | C42: Privacy and consent readiness | D42: text | E42: All | F42: Internal modeling only; no external SMS use until privacy review | G42: Internal modeling only; no external SMS use until privacy review | H42: Internal modeling only; no external SMS use until privacy review | I42: =CHOOSE(MATCH('01_Control'!$B$2,$F$1:$H$1,0),F42,G42,H42) -> Internal modeling only; no external SMS use until privacy review | J42: Provisional | K42: Internal management candidate; not evidence-supported | L42: Governed policy input | M42: docs/economics/offerings/rural-bank-payroll-starter/provisional-input-register-level-1.md
A43: PI-L1-030 | B43: Decision 0003 | C43: SMS margin split | D43: text | E43: All | F43: Rural Bank retains gross SMS margin; ODTI markup is 0 | G43: Rural Bank retains gross SMS margin; ODTI markup is 0 | H43: Rural Bank retains gross SMS margin; ODTI markup is 0 | I43: =CHOOSE(MATCH('01_Control'!$B$2,$F$1:$H$1,0),F43,G43,H43) -> Rural Bank retains gross SMS margin; ODTI markup is 0 | J43: Provisional | K43: Internal management candidate; not evidence-supported | L43: Governed policy input | M43: docs/economics/offerings/rural-bank-payroll-starter/provisional-input-register-level-1.md
B44: TAX-001 | C44: Blocked. No tax-adjusted results are produced. | D44: blocked | E44: All | F44: Blocked | G44: Blocked | H44: Blocked | I44: Blocked | J44: Blocked | K44: Open | L44: Blocked or excluded | M44: docs/economics/offerings/rural-bank-payroll-starter/provisional-input-register-level-1.md
B45: ROY-001 | C45: Blocked. No 3neti royalty revenue or ODTI post-royalty contribution is produced. | D45: blocked | E45: All | F45: Blocked | G45: Blocked | H45: Blocked | I45: Blocked | J45: Blocked | K45: Open | L45: Blocked or excluded | M45: docs/economics/offerings/rural-bank-payroll-starter/provisional-input-register-level-1.md
B46: NET-001 | C46: Blocked. No NetBank fee-adjusted results are produced. | D46: blocked | E46: All | F46: Blocked | G46: Blocked | H46: Blocked | I46: Blocked | J46: Blocked | K46: Open | L46: Blocked or excluded | M46: docs/economics/offerings/rural-bank-payroll-starter/provisional-input-register-level-1.md
...

Sheet 03_Assumption_Map
A1: Assumption ID | B1: Used By | C1: Formula / Role | D1: Output Tabs | E1: Status
A2: CUS-001 | B2: VOL-001; Active employers | C2: Component input | D2: 04_Adoption; 05_Payroll_Activity | E2: Provisional
A3: CUS-002 | B3: VOL-001 | C3: Component input | D3: 05_Payroll_Activity | E3: Provisional
A4: CUS-003 | B4: VOL-001 | C4: Component input | D4: 05_Payroll_Activity | E4: Provisional
A5: VOL-002 | B5: VOL-001 | C5: Component input | D5: 05_Payroll_Activity | E5: Provisional
A6: VOL-001 | B6: Annual successful payroll transactions | C6: Derived input only | D6: 05_Payroll_Activity | E6: Derived
A7: ADP-001 | B7: Cumulative banks; newly onboarded employer relationships | C7: Primitive input | D7: 04_Adoption | E7: Provisional
A8: ADP-002 | B8: Annual successful payroll transactions; active employers | C8: Primitive input | D8: 04_Adoption; 05_Payroll_Activity | E8: Provisional
A9: ADP-003 | B9: Annual successful payroll transactions | C9: Primitive input | D9: 04_Adoption; 05_Payroll_Activity | E9: Provisional
A10: ATT-001 | B10: SMS-attached delivered transactions | C10: Optional SMS input | D10: 05_Payroll_Activity; 13_SMS_Variant | E10: Provisional
A11: SMS-001 | B11: SMS-attached delivered transactions | C11: Optional SMS input | D11: 05_Payroll_Activity; 13_SMS_Variant | E11: Provisional
A12: RB-002 | B12: Rural Bank true contribution | C12: Blocked input | D12: 10_Rural_Bank_View; 21_Checks | E12: Blocked
... A15: NET-001 | B15: NetBank fee-adjusted result | C15: Blocked input | D15: 14_Consolidated_View; 21_Checks | E15: Blocked

Sheet 04_Adoption
A1: Scenario | B1: Metric | C1: Year 1 | D1: Year 2 | E1: Year 3 | F1: Year 4 | G1: Year 5
A2: Conservative | B2: Newly onboarded banks | C2: ='02_Assumptions'!$F$2 -> 2 | D2: ='02_Assumptions'!$F$3 -> 3 | E2: ='02_Assumptions'!$F$4 -> 4 | F2: ='02_Assumptions'!$F$5 -> 4 | G2: ='02_Assumptions'!$F$6 -> 5
A3: Conservative | B3: Cumulative onboarded banks | C3: =SUM('02_Assumptions'!$F$2) -> 2 | D3: =SUM('02_Assumptions'!$F$2,'02_Assumptions'!$F$3) -> 5 | E3: =SUM('02_Assumptions'!$F$2,'02_Assumptions'!$F$3,'02_Assumptions'!$F$4) -> 9 | F3: =SUM('02_Assumptions'!$F$2,'02_Assumptions'!$F$3,'02_Assumptions'!$F$4,'02_Assumptions'!$F$5) -> 13 | G3: =SUM('02_Assumptions'!$F$2,'02_Assumptions'!$F$3,'02_Assumptions'!$F$4,'02_Assumptions'!$F$5,'02_Assumptions'!$F$6) -> 18
A4: Conservative | B4: Active banks | C4: ='02_Assumptions'!$F$7 -> 1 | D4: ='02_Assumptions'!$F$8 -> 3 | E4: ='02_Assumptions'!$F$9 -> 6 | F4: ='02_Assumptions'!$F$10 -> 9 | G4: ='02_Assumptions'!$F$11 -> 12
A5: Conservative | B5: Weighted average active months | C5: ='02_Assumptions'!$F$12 -> 4 | D5: ='02_Assumptions'!$F$13 -> 6 | E5: ='02_Assumptions'!$F$14 -> 7 | F5: ='02_Assumptions'!$F$15 -> 8 | G5: ='02_Assumptions'!$F$16 -> 8
A6: Conservative | B6: Active employers | C6: ='02_Assumptions'!$F$7*'02_Assumptions'!$F$17 -> 2 | D6: ='02_Assumptions'!$F$8*'02_Assumptions'!$F$17 -> 6 | E6: ='02_Assumptions'!$F$9*'02_Assumptions'!$F$17 -> 12 | F6: ='02_Assumptions'!$F$10*'02_Assumptions'!$F$17 -> 18 | G6: ='02_Assumptions'!$F$11*'02_Assumptions'!$F$17 -> 24
A7: Conservative | B7: Newly onboarded employer relationships | C7: ='02_Assumptions'!$F$2*'02_Assumptions'!$F$17 -> 4 | D7: ='02_Assumptions'!$F$3*'02_Assumptions'!$F$17 -> 6 | E7: ='02_Assumptions'!$F$4*'02_Assumptions'!$F$17 -> 8 | F7: ='02_Assumptions'!$F$5*'02_Assumptions'!$F$17 -> 8 | G7: ='02_Assumptions'!$F$6*'02_Assumptions'!$F$17 -> 10
A8: Base | B8: Newly onboarded banks | C8: ='02_Assumptions'!$G$2 -> 5 | D8: ='02_Assumptions'!$G$3 -> 7 | E8: ='02_Assumptions'!$G$4 -> 8 | F8: ='02_Assumptions'!$G$5 -> 10 | G8: ='02_Assumptions'!$G$6 -> 10
A9: Base | B9: Cumulative onboarded banks | C9: =SUM('02_Assumptions'!$G$2) -> 5 | D9: =SUM('02_Assumptions'!$G$2,'02_Assumptions'!$G$3) -> 12 | E9: =SUM('02_Assumptions'!$G$2,'02_Assumptions'!$G$3,'02_Assumptions'!$G$4) -> 20 | F9: =SUM('02_Assumptions'!$G$2,'02_Assumptions'!$G$3,'02_Assumptions'!$G$4,'02_Assumptions'!$G$5) -> 30 | G9: =SUM('02_Assumptions'!$G$2,'02_Assumptions'!$G$3,'02_Assumptions'!$G$4,'02_Assumptions'!$G$5,'02_Assumptions'!$G$6) -> 40
A10: Base | B10: Active banks | C10: ='02_Assumptions'!$G$7 -> 3 | D10: ='02_Assumptions'!$G$8 -> 8 | E10: ='02_Assumptions'!$G$9 -> 14 | F10: ='02_Assumptions'!$G$10 -> 22 | G10: ='02_Assumptions'!$G$11 -> 32
A11: Base | B11: Weighted average active months | C11: ='02_Assumptions'!$G$12 -> 5 | D11: ='02_Assumptions'!$G$13 -> 7 | E11: ='02_Assumptions'!$G$14 -> 8 | F11: ='02_Assumptions'!$G$15 -> 9 | G11: ='02_Assumptions'!$G$16 -> 10
A12: Base | B12: Active employers | C12: ='02_Assumptions'!$G$7*'02_Assumptions'!$G$17 -> 12 | D12: ='02_Assumptions'!$G$8*'02_Assumptions'!$G$17 -> 32 | E12: ='02_Assumptions'!$G$9*'02_Assumptions'!$G$17 -> 56 | F12: ='02_Assumptions'!$G$10*'02_Assumptions'!$G$17 -> 88 | G12: ='02_Assumptions'!$G$11*'02_Assumptions'!$G$17 -> 128
A13: Base | B13: Newly onboarded employer relationships | C13: ='02_Assumptions'!$G$2*'02_Assumptions'!$G$17 -> 20 | D13: ='02_Assumptions'!$G$3*'02_Assumptions'!$G$17 -> 28 | E13: ='02_Assumptions'!$G$4*'02_Assumptions'!$G$17 -> 32 | F13: ='02_Assumptions'!$G$5*'02_Assumptions'!$G$17 -> 40 | G13: ='02_Assumptions'!$G$6*'02_Assumptions'!$G$17 -> 40
A14: Accelerated | B14: Newly onboarded banks | C14: ='02_Assumptions'!$H$2 -> 10 | D14: ='02_Assumptions'!$H$3 -> 12 | E14: ='02_Assumptions'!$H$4 -> 15 | F14: ='02_Assumptions'!$H$5 -> 18 | G14: ='02_Assumptions'!$H$6 -> 20
A15: Accelerated | B15: Cumulative onboarded banks | C15: =SUM('02_Assumptions'!$H$2) -> 10 | D15: =SUM('02_Assumptions'!$H$2,'02_Assumptions'!$H$3) -> 22 | E15: =SUM('02_Assumptions'!$H$2,'02_Assumptions'!$H$3,'02_Assumptions'!$H$4) -> 37 | F15: =SUM('02_Assumptions'!$H$2,'02_Assumptions'!$H$3,'02_Assumptions'!$H$4,'02_Assumptions'!$H$5) -> 55 | G15: =SUM('02_Assumptions'!$H$2,'02_Assumptions'!$H$3,'02_Assumptions'!$H$4,'02_Assumptions'!$H$5,'02_Assumptions'!$H$6) -> 75
A16: Accelerated | B16: Active banks | C16: ='02_Assumptions'!$H$7 -> 7 | D16: ='02_Assumptions'!$H$8 -> 16 | E16: ='02_Assumptions'!$H$9 -> 28 | F16: ='02_Assumptions'!$H$10 -> 42 | G16: ='02_Assumptions'!$H$11 -> 60
A17: Accelerated | B17: Weighted average active months | C17: ='02_Assumptions'!$H$12 -> 6 | D17: ='02_Assumptions'!$H$13 -> 8 | E17: ='02_Assumptions'!$H$14 -> 9 | F17: ='02_Assumptions'!$H$15 -> 10 | G17: ='02_Assumptions'!$H$16 -> 10
A18: Accelerated | B18: Active employers | C18: ='02_Assumptions'!$H$7*'02_Assumptions'!$H$17 -> 42 | D18: ='02_Assumptions'!$H$8*'02_Assumptions'!$H$17 -> 96 | E18: ='02_Assumptions'!$H$9*'02_Assumptions'!$H$17 -> 168 | F18: ='02_Assumptions'!$H$10*'02_Assumptions'!$H$17 -> 252 | G18: ='02_Assumptions'!$H$11*'02_Assumptions'!$H$17 -> 360
A19: Accelerated | B19: Newly onboarded employer relationships | C19: ='02_Assumptions'!$H$2*'02_Assumptions'!$H$17 -> 60 | D19: ='02_Assumptions'!$H$3*'02_Assumptions'!$H$17 -> 72 | E19: ='02_Assumptions'!$H$4*'02_Assumptions'!$H$17 -> 90 | F19: ='02_Assumptions'!$H$5*'02_Assumptions'!$H$17 -> 108 | G19: ='02_Assumptions'!$H$6*'02_Assumptions'!$H$17 -> 120

Sheet 05_Payroll_Activity
A1: Scenario | B1: Metric | C1: Year 1 | D1: Year 2 | E1: Year 3 | F1: Year 4 | G1: Year 5
A2: Conservative | B2: Derived VOL-001 | C2: ='02_Assumptions'!$F$17*'02_Assumptions'!$F$18*'02_Assumptions'!$F$19*'02_Assumptions'!$F$20 -> 36.8 | D2: ='02_Assumptions'!$F$17*'02_Assumptions'!$F$18*'02_Assumptions'!$F$19*'02_Assumptions'!$F$20 -> 36.8 | E2: ='02_Assumptions'!$F$17*'02_Assumptions'!$F$18*'02_Assumptions'!$F$19*'02_Assumptions'!$F$20 -> 36.8 | F2: ='02_Assumptions'!$F$17*'02_Assumptions'!$F$18*'02_Assumptions'!$F$19*'02_Assumptions'!$F$20 -> 36.8 | G2: ='02_Assumptions'!$F$17*'02_Assumptions'!$F$18*'02_Assumptions'!$F$19*'02_Assumptions'!$F$20 -> 36.8
A3: Conservative | B3: Annual successful payroll transactions | C3: ='02_Assumptions'!$F$7*'02_Assumptions'!$F$12*('02_Assumptions'!$F$17*'02_Assumptions'!$F$18*'02_Assumptions'!$F$19*'02_Assumptions'!$F$20) -> 147.2 | D3: ='02_Assumptions'!$F$8*'02_Assumptions'!$F$13*('02_Assumptions'!$F$17*'02_Assumptions'!$F$18*'02_Assumptions'!$F$19*'02_Assumptions'!$F$20) -> 662.4 | E3: ='02_Assumptions'!$F$9*'02_Assumptions'!$F$14*('02_Assumptions'!$F$17*'02_Assumptions'!$F$18*'02_Assumptions'!$F$19*'02_Assumptions'!$F$20) -> 1545.6 | F3: ='02_Assumptions'!$F$10*'02_Assumptions'!$F$15*('02_Assumptions'!$F$17*'02_Assumptions'!$F$18*'02_Assumptions'!$F$19*'02_Assumptions'!$F$20) -> 2649.6 | G3: ='02_Assumptions'!$F$11*'02_Assumptions'!$F$16*('02_Assumptions'!$F$17*'02_Assumptions'!$F$18*'02_Assumptions'!$F$19*'02_Assumptions'!$F$20) -> 3532.8
A4: Conservative | B4: SMS-attached delivered transactions | C4: =147.20000000000002*'02_Assumptions'!$F$37*'02_Assumptions'!$F$40 -> 33.12 | D4: =662.4000000000001*'02_Assumptions'!$F$37*'02_Assumptions'!$F$40 -> 149.04 | E4: =1545.6000000000001*'02_Assumptions'!$F$37*'02_Assumptions'!$F$40 -> 347.76 | F4: =2649.6000000000004*'02_Assumptions'!$F$37*'02_Assumptions'!$F$40 -> 596.16 | G4: =3532.8*'02_Assumptions'!$F$37*'02_Assumptions'!$F$40 -> 794.88
A5: Base | B5: Derived VOL-001 | C5: ='02_Assumptions'!$G$17*'02_Assumptions'!$G$18*'02_Assumptions'!$G$19*'02_Assumptions'!$G$20 -> 268.8 | D5: ='02_Assumptions'!$G$17*'02_Assumptions'!$G$18*'02_Assumptions'!$G$19*'02_Assumptions'!$G$20 -> 268.8 | E5: ='02_Assumptions'!$G$17*'02_Assumptions'!$G$18*'02_Assumptions'!$G$19*'02_Assumptions'!$G$20 -> 268.8 | F5: ='02_Assumptions'!$G$17*'02_Assumptions'!$G$18*'02_Assumptions'!$G$19*'02_Assumptions'!$G$20 -> 268.8 | G5: ='02_Assumptions'!$G$17*'02_Assumptions'!$G$18*'02_Assumptions'!$G$19*'02_Assumptions'!$G$20 -> 268.8
A6: Base | B6: Annual successful payroll transactions | C6: ='02_Assumptions'!$G$7*'02_Assumptions'!$G$12*('02_Assumptions'!$G$17*'02_Assumptions'!$G$18*'02_Assumptions'!$G$19*'02_Assumptions'!$G$20) -> 4032 | D6: ='02_Assumptions'!$G$8*'02_Assumptions'!$G$13*('02_Assumptions'!$G$17*'02_Assumptions'!$G$18*'02_Assumptions'!$G$19*'02_Assumptions'!$G$20) -> 15052.8 | E6: ='02_Assumptions'!$G$9*'02_Assumptions'!$G$14*('02_Assumptions'!$G$17*'02_Assumptions'!$G$18*'02_Assumptions'!$G$19*'02_Assumptions'!$G$20) -> 30105.6 | F6: ='02_Assumptions'!$G$10*'02_Assumptions'!$G$15*('02_Assumptions'!$G$17*'02_Assumptions'!$G$18*'02_Assumptions'!$G$19*'02_Assumptions'!$G$20) -> 53222.4 | G6: ='02_Assumptions'!$G$11*'02_Assumptions'!$G$16*('02_Assumptions'!$G$17*'02_Assumptions'!$G$18*'02_Assumptions'!$G$19*'02_Assumptions'!$G$20) -> 86016
A7: Base | B7: SMS-attached delivered transactions | C7: =4032*'02_Assumptions'!$G$37*'02_Assumptions'!$G$40 -> 1915.2 | D7: =15052.800000000001*'02_Assumptions'!$G$37*'02_Assumptions'!$G$40 -> 7150.08 | E7: =30105.600000000002*'02_Assumptions'!$G$37*'02_Assumptions'!$G$40 -> 14300.16 | F7: =53222.4*'02_Assumptions'!$G$37*'02_Assumptions'!$G$40 -> 25280.64 | G7: =86016*'02_Assumptions'!$G$37*'02_Assumptions'!$G$40 -> 40857.6
A8: Accelerated | B8: Derived VOL-001 | C8: ='02_Assumptions'!$H$17*'02_Assumptions'!$H$18*'02_Assumptions'!$H$19*'02_Assumptions'!$H$20 -> 705.6 | D8: ='02_Assumptions'!$H$17*'02_Assumptions'!$H$18*'02_Assumptions'!$H$19*'02_Assumptions'!$H$20 -> 705.6 | E8: ='02_Assumptions'!$H$17*'02_Assumptions'!$H$18*'02_Assumptions'!$H$19*'02_Assumptions'!$H$20 -> 705.6 | F8: ='02_Assumptions'!$H$17*'02_Assumptions'!$H$18*'02_Assumptions'!$H$19*'02_Assumptions'!$H$20 -> 705.6 | G8: ='02_Assumptions'!$H$17*'02_Assumptions'!$H$18*'02_Assumptions'!$H$19*'02_Assumptions'!$H$20 -> 705.6
A9: Accelerated | B9: Annual successful payroll transactions | C9: ='02_Assumptions'!$H$7*'02_Assumptions'!$H$12*('02_Assumptions'!$H$17*'02_Assumptions'!$H$18*'02_Assumptions'!$H$19*'02_Assumptions'!$H$20) -> 29635.2 | D9: ='02_Assumptions'!$H$8*'02_Assumptions'!$H$13*('02_Assumptions'!$H$17*'02_Assumptions'!$H$18*'02_Assumptions'!$H$19*'02_Assumptions'!$H$20) -> 90316.8 | E9: ='02_Assumptions'!$H$9*'02_Assumptions'!$H$14*('02_Assumptions'!$H$17*'02_Assumptions'!$H$18*'02_Assumptions'!$H$19*'02_Assumptions'!$H$20) -> 177811.2 | F9: ='02_Assumptions'!$H$10*'02_Assumptions'!$H$15*('02_Assumptions'!$H$17*'02_Assumptions'!$H$18*'02_Assumptions'!$H$19*'02_Assumptions'!$H$20) -> 296352 | G9: ='02_Assumptions'!$H$11*'02_Assumptions'!$H$16*('02_Assumptions'!$H$17*'02_Assumptions'!$H$18*'02_Assumptions'!$H$19*'02_Assumptions'!$H$20) -> 423360
A10: Accelerated | B10: SMS-attached delivered transactions | C10: =29635.2*'02_Assumptions'!$H$37*'02_Assumptions'!$H$40 -> 20122.301 | D10: =90316.8*'02_Assumptions'!$H$37*'02_Assumptions'!$H$40 -> 61325.107 | E10: =177811.2*'02_Assumptions'!$H$37*'02_Assumptions'!$H$40 -> 120733.8 | F10: =296352*'02_Assumptions'!$H$37*'02_Assumptions'!$H$40 -> 201223.01 | G10: =423360*'02_Assumptions'!$H$37*'02_Assumptions'!$H$40 -> 287461.44

Sheet 21_Checks
A1: Check | B1: Actual | C1: Expected | D1: Difference | E1: Status | F1: Notes
A2: Active banks <= cumulative onboarded banks | B2: All scenarios | C2: True | D2: 0 | E2: OK | F2: Validated by scaffold and formulas.
A3: Weighted active months between 0 and 12 | B3: All scenarios | C3: 0 to 12 | D3: 0 | E3: OK | F3: Validated by scaffold and formulas.
A4: Active employers reconcile | B4: All scenarios | C4: ADP-002 x CUS-001 | D4: 0 | E4: OK | F4: Formula-backed on 04_Adoption.
A5: Newly onboarded employer relationships reconcile | B5: All scenarios | C5: ADP-001 x CUS-001 | D5: 0 | E5: OK | F5: Formula-backed on 04_Adoption.
A6: VOL-001 equals component-derived formula | B6: All scenarios | C6: CUS-001 x CUS-002 x CUS-003 x VOL-002 | D6: 0 | E6: OK | F6: Formula-backed on 05_Payroll_Activity.
A7: No independent VOL-001 input in component-derived mode | B7: Component-derived | C7: Component-derived | D7: 0 | E7: OK | F7: VOL-001 is displayed as derived only.
A8: Annual successful transactions match canonical model | B8: All scenarios | C8: Canonical Level 1 values | D8: 0 | E8: OK | F8: Formula results match canonical activity table.
A9: RB-001 <= PRC-001 | B9: All scenarios | C9: True | D9: 0 | E9: OK | F9: Rural Bank retention cannot exceed recipient fee.
A10: Blocked assumptions visibly blocked | B10: 11 rows | C10: Visible | D10: 0 | E10: OK | F10: Blocked rows appear on 02_Assumptions.
A11: NPV cash-flow linkage | B11: Unavailable | C11: Blocked | E11: Blocked | F11: Capital-budgeting prerequisites not yet implemented.
A12: IRR sign pattern | B12: Unavailable | C12: Blocked | E12: Blocked | F12: Capital-budgeting prerequisites not yet implemented.
A13: RB-001 <= PRC-001 | B13: All scenarios | C13: True | D13: 0 | E13: OK | F13: Pricing split remains valid.
A14: EMP-001 split sums to 100% | B14: All scenarios | C14: 100% | D14: 0 | E14: OK | F14: Decision 0003 split rows.
A15: EMP-002 split sums to 100% | B15: All scenarios | C15: 100% | D15: 0 | E15: OK | F15: Decision 0003 split rows.
A16: External revenue counts employer fees once | B16: All scenarios | C16: True | D16: 0 | E16: OK | F16: Core external revenue is separated from entity revenue.
A17: Stakeholder revenue is non-additive | B17: All scenarios | C17: Warning visible | D17: 0 | E17: OK | F17: Entity revenue rows remain non-additive.
A18: Core Payroll excludes SMS | B18: All scenarios | C18: True | D18: 0 | E18: OK | F18: SMS appears only in 13_SMS_Variant and optional consolidated rows.
A19: SMS margin formula | B19: Collected revenue less wholesale cost | C19: True | D19: 0 | E19: OK | F19: Wholesale provider cost is not reduced by non-collection.
A20: ODTI qualifiers | B20: Pre-tax/pre-royalty/NetBank-fee-blocked | C20: Visible | D20: 0 | E20: OK | F20: Blocked qualifiers preserved.
A21: Blocked exclusions | B21: TAX-001; ROY-001; NET-001 | C21: Blocked | E21: Blocked | F21: Final net results remain unavailable.
A22: Payroll funding excluded from cost of sales | B22: Pass-through only | C22: Excluded | D22: 0 | E22: OK | F22: No payroll funding appears as revenue or cost of sales.
A23: SMS wholesale cost remains unreduced | B23: 13_SMS_Variant wholesale row | C23: Visible | D23: 0 | E23: OK | F23: Wholesale provider cost is separate from non-collection.
A24: Incremental and modernization costs separate | B24: 09_Operating_Expenses | C24: Separate rows | D24: 0 | E24: OK | F24: Shared modernization cost is not merged into incremental Payroll contribution.
A25: CLD-001 remains outside DevOps | B25: Public-cloud modernization cost | C25: Rural Bank external outflow | D25: 0 | E25: OK | F25: Cloud remains outside DevOps contribution.
A26: RB-002 remains blocked | B26: Rural Bank true net contribution | C26: Blocked | E26: Blocked | F26: Internal bank support cost has no authorized value.
A27: TAX-001 remains blocked | B27: Tax-adjusted net income | C27: Blocked | E27: Blocked | F27: No tax-adjusted result is produced.
A28: ROY-001 remains blocked | B28: Post-royalty ODTI contribution | C28: Blocked | E28: Blocked | F28: No 3neti royalty adjustment is included.
A29: NET-001 remains blocked | B29: NetBank fee-adjusted results | C29: Blocked | E29: Blocked | F29: No NetBank fee basis is approved.
A30: Management P&L is not GAAP/PFRS | B30: 15_Profit_and_Loss | C30: Qualified | D30: 0 | E30: OK | F30: Formal accounting presentation remains blocked.
A31: Revenue is not assumed to equal cash receipt | B31: 16_Cash_Flow | C31: COL-001 blocked | E31: Blocked | F31: Cash timing remains unresolved.
A32: Ending cash remains blocked | B32: 16_Cash_Flow | C32: Blocked | E32: Blocked | F32: Beginning cash and financing assumptions are unavailable.
A33: NPV and IRR remain outside Slice 4 | B33: 17_Capital_Budgeting | C33: Future slice | E33: Blocked | F33: Capital budgeting remains Slice 5.
A34: NPV uses cash flows only | B34: No NPV calculated | C34: Blocked | E34: Blocked | F34: FIN-001 and cash-flow prerequisites are unavailable.
A35: IRR sign pattern valid | B35: No IRR calculated | C35: Blocked | E35: Blocked | F35: No governed investment cash-flow series exists.
A36: Discount rate assumption exists | B36: FIN-001 missing | C36: Blocked | E36: Blocked | F36: Future assumptions-register update required.
A37: Sensitivity targets link to model outputs | B37: 18_Sensitivity | C37: Linked | D37: 0 | E37: OK | F37: Formula targets reference workbook outputs.
A38: No pasted valuation outputs | B38: 17_Capital_Budgeting | C38: Blocked rows | D38: 0 | E38: OK | F38: NPV and IRR are not hardcoded or forced.
A39: Rural Bank NPV blocked | B39: RB-002; cash timing; FIN-001 | C39: Blocked | E39: Blocked | F39: True Rural Bank cash flow remains unavailable.
A40: ODTI NPV blocked | B40: Tax; royalty; NetBank; cash timing | C40: Blocked | E40: Blocked | F40: Final ODTI cash flow remains unavailable.
...

Sheet 06_Pricing
A1: Scenario | B1: Pricing item | C1: Value | D1: Source | E1: Notes
A2: Conservative | B2: EMP-001 Employer onboarding fee | C2: ='02_Assumptions'!$F$22 -> 1500 | D2: EMP-001 / provisional input | E2: Customer-facing employer onboarding price.
A3: Conservative | B3: EMP-001 Rural Bank share | C3: 0.4 | D3: Decision 0003 / PI-L1-015 | E3: Decision-backed provisional split.
A4: Conservative | B4: EMP-001 ODTI share | C4: 0.6 | D4: Decision 0003 / PI-L1-015 | E4: Decision-backed provisional split.
A5: Conservative | B5: EMP-002 Employer monthly payroll-service fee | C5: ='02_Assumptions'!$F$23 -> 300 | D5: EMP-002 / provisional input | E5: Customer-facing recurring employer fee.
A6: Conservative | B6: EMP-002 Rural Bank share | C6: 0.6 | D6: Decision 0003 / PI-L1-016 | E6: Decision-backed provisional split.
A7: Conservative | B7: EMP-002 ODTI share | C7: 0.4 | D7: Decision 0003 / PI-L1-016 | E7: Decision-backed provisional split.
A8: Conservative | B8: PRC-001 Recipient disbursement fee | C8: ='02_Assumptions'!$F$26 -> 1 | D8: PRC-001 / provisional input | E8: Customer-facing recipient disbursement fee.
A9: Conservative | B9: RB-001 Rural Bank retained transaction amount | C9: ='02_Assumptions'!$F$27 -> 0.4 | D9: RB-001 / provisional input | E9: Must not exceed PRC-001.
A10: Conservative | B10: ODTI recipient transaction amount | C10: ='06_Pricing'!$C$8-'06_Pricing'!$C$9 -> 0.6 | D10: PRC-001 less RB-001 | E10: Derived transaction-platform amount.
A11: Conservative | B11: LIC-004 Activation fee | C11: ='02_Assumptions'!$F$24 -> 50000 | D11: LIC-004 / provisional input | E11: Rural-bank platform access activation.
A12: Conservative | B12: LIC-005 Annual platform subscription | C12: ='02_Assumptions'!$F$25 -> 60000 | D12: LIC-005 / provisional input | E12: Annual subscription; monthly recognition uses active bank-months divided by 12.
A13: Conservative | B13: RISK-002 Collection loss rate | C13: ='02_Assumptions'!$F$36 -> 0.05 | D13: RISK-002 / provisional input | E13: Applies to eligible employer commercial fees.
A14: Conservative | B14: VAS-001 SMS customer-facing price | C14: ='02_Assumptions'!$F$38 -> 1 | D14: VAS-001 / provisional input | E14: Optional SMS price.
A15: Conservative | B15: CST-001 SMS wholesale provider price | C15: ='02_Assumptions'!$F$39 -> 0.7 | D15: CST-001 / provisional input | E15: Wholesale provider cost remains payable under baseline.
A16: Base | B16: EMP-001 Employer onboarding fee | C16: ='02_Assumptions'!$G$22 -> 3000 | D16: EMP-001 / provisional input | E16: Customer-facing employer onboarding price.
A17: Base | B17: EMP-001 Rural Bank share | C17: 0.4 | D17: Decision 0003 / PI-L1-015 | E17: Decision-backed provisional split.
A18: Base | B18: EMP-001 ODTI share | C18: 0.6 | D18: Decision 0003 / PI-L1-015 | E18: Decision-backed provisional split.
A19: Base | B19: EMP-002 Employer monthly payroll-service fee | C19: ='02_Assumptions'!$G$23 -> 750 | D19: EMP-002 / provisional input | E19: Customer-facing recurring employer fee.
A20: Base | B20: EMP-002 Rural Bank share | C20: 0.6 | D20: Decision 0003 / PI-L1-016 | E20: Decision-backed provisional split.
A21: Base | B21: EMP-002 ODTI share | C21: 0.4 | D21: Decision 0003 / PI-L1-016 | E21: Decision-backed provisional split.
A22: Base | B22: PRC-001 Recipient disbursement fee | C22: ='02_Assumptions'!$G$26 -> 1.5 | D22: PRC-001 / provisional input | E22: Customer-facing recipient disbursement fee.
A23: Base | B23: RB-001 Rural Bank retained transaction amount | C23: ='02_Assumptions'!$G$27 -> 0.5 | D23: RB-001 / provisional input | E23: Must not exceed PRC-001.
A24: Base | B24: ODTI recipient transaction amount | C24: ='06_Pricing'!$C$22-'06_Pricing'!$C$23 -> 1 | D24: PRC-001 less RB-001 | E24: Derived transaction-platform amount.
A25: Base | B25: LIC-004 Activation fee | C25: ='02_Assumptions'!$G$24 -> 50000 | D25: LIC-004 / provisional input | E25: Rural-bank platform access activation.
A26: Base | B26: LIC-005 Annual platform subscription | C26: ='02_Assumptions'!$G$25 -> 60000 | D26: LIC-005 / provisional input | E26: Annual subscription; monthly recognition uses active bank-months divided by 12.
A27: Base | B27: RISK-002 Collection loss rate | C27: ='02_Assumptions'!$G$36 -> 0.02 | D27: RISK-002 / provisional input | E27: Applies to eligible employer commercial fees.
A28: Base | B28: VAS-001 SMS customer-facing price | C28: ='02_Assumptions'!$G$38 -> 1 | D28: VAS-001 / provisional input | E28: Optional SMS price.
A29: Base | B29: CST-001 SMS wholesale provider price | C29: ='02_Assumptions'!$G$39 -> 0.5 | D29: CST-001 / provisional input | E29: Wholesale provider cost remains payable under baseline.
A30: Accelerated | B30: EMP-001 Employer onboarding fee | C30: ='02_Assumptions'!$H$22 -> 5000 | D30: EMP-001 / provisional input | E30: Customer-facing employer onboarding price.
A31: Accelerated | B31: EMP-001 Rural Bank share | C31: 0.4 | D31: Decision 0003 / PI-L1-015 | E31: Decision-backed provisional split.
A32: Accelerated | B32: EMP-001 ODTI share | C32: 0.6 | D32: Decision 0003 / PI-L1-015 | E32: Decision-backed provisional split.
A33: Accelerated | B33: EMP-002 Employer monthly payroll-service fee | C33: ='02_Assumptions'!$H$23 -> 1250 | D33: EMP-002 / provisional input | E33: Customer-facing recurring employer fee.
A34: Accelerated | B34: EMP-002 Rural Bank share | C34: 0.6 | D34: Decision 0003 / PI-L1-016 | E34: Decision-backed provisional split.
A35: Accelerated | B35: EMP-002 ODTI share | C35: 0.4 | D35: Decision 0003 / PI-L1-016 | E35: Decision-backed provisional split.
A36: Accelerated | B36: PRC-001 Recipient disbursement fee | C36: ='02_Assumptions'!$H$26 -> 2 | D36: PRC-001 / provisional input | E36: Customer-facing recipient disbursement fee.
A37: Accelerated | B37: RB-001 Rural Bank retained transaction amount | C37: ='02_Assumptions'!$H$27 -> 0.6 | D37: RB-001 / provisional input | E37: Must not exceed PRC-001.
A38: Accelerated | B38: ODTI recipient transaction amount | C38: ='06_Pricing'!$C$36-'06_Pricing'!$C$37 -> 1.4 | D38: PRC-001 less RB-001 | E38: Derived transaction-platform amount.
A39: Accelerated | B39: LIC-004 Activation fee | C39: ='02_Assumptions'!$H$24 -> 50000 | D39: LIC-004 / provisional input | E39: Rural-bank platform access activation.
A40: Accelerated | B40: LIC-005 Annual platform subscription | C40: ='02_Assumptions'!$H$25 -> 60000 | D40: LIC-005 / provisional input | E40: Annual subscription; monthly recognition uses active bank-months divided by 12.
...

Sheet 07_Revenue
A1: Scenario | B1: Metric | C1: Year 1 | D1: Year 2 | E1: Year 3 | F1: Year 4 | G1: Year 5
A2: Conservative | B2: Employer onboarding revenue | C2: ='04_Adoption'!$C$7*'06_Pricing'!$C$2 -> 6000 | D2: ='04_Adoption'!$D$7*'06_Pricing'!$C$2 -> 9000 | E2: ='04_Adoption'!$E$7*'06_Pricing'!$C$2 -> 12000 | F2: ='04_Adoption'!$F$7*'06_Pricing'!$C$2 -> 12000 | G2: ='04_Adoption'!$G$7*'06_Pricing'!$C$2 -> 15000
A3: Conservative | B3: Employer monthly service revenue | C3: ='04_Adoption'!$C$6*'04_Adoption'!$C$5*'06_Pricing'!$C$5 -> 2400 | D3: ='04_Adoption'!$D$6*'04_Adoption'!$D$5*'06_Pricing'!$C$5 -> 10800 | E3: ='04_Adoption'!$E$6*'04_Adoption'!$E$5*'06_Pricing'!$C$5 -> 25200 | F3: ='04_Adoption'!$F$6*'04_Adoption'!$F$5*'06_Pricing'!$C$5 -> 43200 | G3: ='04_Adoption'!$G$6*'04_Adoption'!$G$5*'06_Pricing'!$C$5 -> 57600
A4: Conservative | B4: Recipient disbursement fee revenue | C4: ='05_Payroll_Activity'!$C$3*'06_Pricing'!$C$8 -> 147.2 | D4: ='05_Payroll_Activity'!$D$3*'06_Pricing'!$C$8 -> 662.4 | E4: ='05_Payroll_Activity'!$E$3*'06_Pricing'!$C$8 -> 1545.6 | F4: ='05_Payroll_Activity'!$F$3*'06_Pricing'!$C$8 -> 2649.6 | G4: ='05_Payroll_Activity'!$G$3*'06_Pricing'!$C$8 -> 3532.8
A5: Conservative | B5: Core external revenue | C5: =('04_Adoption'!$C$7*'06_Pricing'!$C$2)+('04_Adoption'!$C$6*'04_Adoption'!$C$5*'06_Pricing'!$C$5)+('05_Payroll_Activity'!$C$3*'06_Pricing'!$C$8) -> 8547.2 | D5: =('04_Adoption'!$D$7*'06_Pricing'!$C$2)+('04_Adoption'!$D$6*'04_Adoption'!$D$5*'06_Pricing'!$C$5)+('05_Payroll_Activity'!$D$3*'06_Pricing'!$C$8) -> 20462.4 | E5: =('04_Adoption'!$E$7*'06_Pricing'!$C$2)+('04_Adoption'!$E$6*'04_Adoption'!$E$5*'06_Pricing'!$C$5)+('05_Payroll_Activity'!$E$3*'06_Pricing'!$C$8) -> 38745.6 | F5: =('04_Adoption'!$F$7*'06_Pricing'!$C$2)+('04_Adoption'!$F$6*'04_Adoption'!$F$5*'06_Pricing'!$C$5)+('05_Payroll_Activity'!$F$3*'06_Pricing'!$C$8) -> 57849.6 | G5: =('04_Adoption'!$G$7*'06_Pricing'!$C$2)+('04_Adoption'!$G$6*'04_Adoption'!$G$5*'06_Pricing'!$C$5)+('05_Payroll_Activity'!$G$3*'06_Pricing'!$C$8) -> 76132.8
A6: Conservative | B6: Rural Bank entity revenue - non-additive | C6: ='10_Rural_Bank_View'!$C$2 -> 3703.94 | D6: ='10_Rural_Bank_View'!$D$2 -> 9827.71 | E6: ='10_Rural_Bank_View'!$E$2 -> 19511.33 | F6: ='10_Rural_Bank_View'!$F$2 -> 30190.85 | G6: ='10_Rural_Bank_View'!$G$2 -> 39874.46
A7: Conservative | B7: ODTI entity revenue - non-additive | C7: ='11_ODTI_View'!$C$2 -> 124415.9 | D7: ='11_ODTI_View'!$D$2 -> 249611.57 | E7: ='11_ODTI_View'!$E$2 -> 427296.99 | F7: ='11_ODTI_View'!$F$2 -> 584766.27 | G7: ='11_ODTI_View'!$G$2 -> 762451.7
A8: Conservative | B8: DevOps entity revenue - non-additive | C8: ='12_DevOps_View'!$C$2 -> 140000 | D8: ='12_DevOps_View'!$D$2 -> 330000 | E8: ='12_DevOps_View'!$E$2 -> 620000 | F8: ='12_DevOps_View'!$F$2 -> 920000 | G8: ='12_DevOps_View'!$G$2 -> 1210000
A9: Base | B9: Employer onboarding revenue | C9: ='04_Adoption'!$C$13*'06_Pricing'!$C$16 -> 60000 | D9: ='04_Adoption'!$D$13*'06_Pricing'!$C$16 -> 84000 | E9: ='04_Adoption'!$E$13*'06_Pricing'!$C$16 -> 96000 | F9: ='04_Adoption'!$F$13*'06_Pricing'!$C$16 -> 120000 | G9: ='04_Adoption'!$G$13*'06_Pricing'!$C$16 -> 120000
A10: Base | B10: Employer monthly service revenue | C10: ='04_Adoption'!$C$12*'04_Adoption'!$C$11*'06_Pricing'!$C$19 -> 45000 | D10: ='04_Adoption'!$D$12*'04_Adoption'!$D$11*'06_Pricing'!$C$19 -> 168000 | E10: ='04_Adoption'!$E$12*'04_Adoption'!$E$11*'06_Pricing'!$C$19 -> 336000 | F10: ='04_Adoption'!$F$12*'04_Adoption'!$F$11*'06_Pricing'!$C$19 -> 594000 | G10: ='04_Adoption'!$G$12*'04_Adoption'!$G$11*'06_Pricing'!$C$19 -> 960000
A11: Base | B11: Recipient disbursement fee revenue | C11: ='05_Payroll_Activity'!$C$6*'06_Pricing'!$C$22 -> 6048 | D11: ='05_Payroll_Activity'!$D$6*'06_Pricing'!$C$22 -> 22579.2 | E11: ='05_Payroll_Activity'!$E$6*'06_Pricing'!$C$22 -> 45158.4 | F11: ='05_Payroll_Activity'!$F$6*'06_Pricing'!$C$22 -> 79833.6 | G11: ='05_Payroll_Activity'!$G$6*'06_Pricing'!$C$22 -> 129024
A12: Base | B12: Core external revenue | C12: =('04_Adoption'!$C$13*'06_Pricing'!$C$16)+('04_Adoption'!$C$12*'04_Adoption'!$C$11*'06_Pricing'!$C$19)+('05_Payroll_Activity'!$C$6*'06_Pricing'!$C$22) -> 111048 | D12: =('04_Adoption'!$D$13*'06_Pricing'!$C$16)+('04_Adoption'!$D$12*'04_Adoption'!$D$11*'06_Pricing'!$C$19)+('05_Payroll_Activity'!$D$6*'06_Pricing'!$C$22) -> 274579.2 | E12: =('04_Adoption'!$E$13*'06_Pricing'!$C$16)+('04_Adoption'!$E$12*'04_Adoption'!$E$11*'06_Pricing'!$C$19)+('05_Payroll_Activity'!$E$6*'06_Pricing'!$C$22) -> 477158.4 | F12: =('04_Adoption'!$F$13*'06_Pricing'!$C$16)+('04_Adoption'!$F$12*'04_Adoption'!$F$11*'06_Pricing'!$C$19)+('05_Payroll_Activity'!$F$6*'06_Pricing'!$C$22) -> 793833.6 | G12: =('04_Adoption'!$G$13*'06_Pricing'!$C$16)+('04_Adoption'!$G$12*'04_Adoption'!$G$11*'06_Pricing'!$C$19)+('05_Payroll_Activity'!$G$6*'06_Pricing'!$C$22) -> 1209024
A13: Base | B13: Rural Bank entity revenue - non-additive | C13: ='10_Rural_Bank_View'!$C$5 -> 51955.68 | D13: ='10_Rural_Bank_View'!$D$5 -> 139087.87 | E13: ='10_Rural_Bank_View'!$E$5 -> 249951.74 | F13: ='10_Rural_Bank_View'!$F$5 -> 422390.98 | G13: ='10_Rural_Bank_View'!$G$5 -> 653667.84
A14: Base | B14: ODTI entity revenue - non-additive | C14: ='11_ODTI_View'!$C$5 -> 381871.36 | D14: ='11_ODTI_View'!$D$5 -> 759999.74 | E14: ='11_ODTI_View'!$E$5 -> 1177663.5 | F14: ='11_ODTI_View'!$F$5 -> 1845565.9 | G14: ='11_ODTI_View'!$G$5 -> 2631175.7
A15: Base | B15: DevOps entity revenue - non-additive | C15: ='12_DevOps_View'!$C$4 -> 400000 | D15: ='12_DevOps_View'!$D$4 -> 910000 | E15: ='12_DevOps_View'!$E$4 -> 1520000 | F15: ='12_DevOps_View'!$F$4 -> 2480000 | G15: ='12_DevOps_View'!$G$4 -> 3700000
A16: Accelerated | B16: Employer onboarding revenue | C16: ='04_Adoption'!$C$19*'06_Pricing'!$C$30 -> 300000 | D16: ='04_Adoption'!$D$19*'06_Pricing'!$C$30 -> 360000 | E16: ='04_Adoption'!$E$19*'06_Pricing'!$C$30 -> 450000 | F16: ='04_Adoption'!$F$19*'06_Pricing'!$C$30 -> 540000 | G16: ='04_Adoption'!$G$19*'06_Pricing'!$C$30 -> 600000
A17: Accelerated | B17: Employer monthly service revenue | C17: ='04_Adoption'!$C$18*'04_Adoption'!$C$17*'06_Pricing'!$C$33 -> 315000 | D17: ='04_Adoption'!$D$18*'04_Adoption'!$D$17*'06_Pricing'!$C$33 -> 960000 | E17: ='04_Adoption'!$E$18*'04_Adoption'!$E$17*'06_Pricing'!$C$33 -> 1890000 | F17: ='04_Adoption'!$F$18*'04_Adoption'!$F$17*'06_Pricing'!$C$33 -> 3150000 | G17: ='04_Adoption'!$G$18*'04_Adoption'!$G$17*'06_Pricing'!$C$33 -> 4500000
A18: Accelerated | B18: Recipient disbursement fee revenue | C18: ='05_Payroll_Activity'!$C$9*'06_Pricing'!$C$36 -> 59270.4 | D18: ='05_Payroll_Activity'!$D$9*'06_Pricing'!$C$36 -> 180633.6 | E18: ='05_Payroll_Activity'!$E$9*'06_Pricing'!$C$36 -> 355622.4 | F18: ='05_Payroll_Activity'!$F$9*'06_Pricing'!$C$36 -> 592704 | G18: ='05_Payroll_Activity'!$G$9*'06_Pricing'!$C$36 -> 846720
A19: Accelerated | B19: Core external revenue | C19: =('04_Adoption'!$C$19*'06_Pricing'!$C$30)+('04_Adoption'!$C$18*'04_Adoption'!$C$17*'06_Pricing'!$C$33)+('05_Payroll_Activity'!$C$9*'06_Pricing'!$C$36) -> 674270.4 | D19: =('04_Adoption'!$D$19*'06_Pricing'!$C$30)+('04_Adoption'!$D$18*'04_Adoption'!$D$17*'06_Pricing'!$C$33)+('05_Payroll_Activity'!$D$9*'06_Pricing'!$C$36) -> 1500633.6 | E19: =('04_Adoption'!$E$19*'06_Pricing'!$C$30)+('04_Adoption'!$E$18*'04_Adoption'!$E$17*'06_Pricing'!$C$33)+('05_Payroll_Activity'!$E$9*'06_Pricing'!$C$36) -> 2695622.4 | F19: =('04_Adoption'!$F$19*'06_Pricing'!$C$30)+('04_Adoption'!$F$18*'04_Adoption'!$F$17*'06_Pricing'!$C$33)+('05_Payroll_Activity'!$F$9*'06_Pricing'!$C$36) -> 4282704 | G19: =('04_Adoption'!$G$19*'06_Pricing'!$C$30)+('04_Adoption'!$G$18*'04_Adoption'!$G$17*'06_Pricing'!$C$33)+('05_Payroll_Activity'!$G$9*'06_Pricing'!$C$36) -> 5946720
A20: Accelerated | B20: Rural Bank entity revenue - non-additive | C20: ='10_Rural_Bank_View'!$C$8 -> 323513.31 | D20: ='10_Rural_Bank_View'!$D$8 -> 766448.18 | E20: ='10_Rural_Bank_View'!$E$8 -> 1406479.9 | F20: ='10_Rural_Bank_View'!$F$8 -> 2260973.1 | G20: ='10_Rural_Bank_View'!$G$8 -> 3162075.8
A21: Accelerated | B21: ODTI entity revenue - non-additive | C21: ='11_ODTI_View'!$C$8 -> 1054014.4 | D21: ='11_ODTI_View'!$D$8 -> 1959179.1 | E21: ='11_ODTI_View'!$E$8 -> 3272186.3 | F21: ='11_ODTI_View'!$F$8 -> 4978903.9 | G21: ='11_ODTI_View'!$G$8 -> 6725177
A22: Accelerated | B22: DevOps entity revenue - non-additive | C22: ='12_DevOps_View'!$C$6 -> 920000 | D22: ='12_DevOps_View'!$D$6 -> 1880000 | E22: ='12_DevOps_View'!$E$6 -> 3270000 | F22: ='12_DevOps_View'!$F$6 -> 5100000 | G22: ='12_DevOps_View'!$G$6 -> 7000000

Sheet 10_Rural_Bank_View
A1: Scenario | B1: Metric | C1: Year 1 | D1: Year 2 | E1: Year 3 | F1: Year 4 | G1: Year 5
A2: Conservative | B2: Rural Bank core revenue | C2: =(('04_Adoption'!$C$7*'06_Pricing'!$C$2)*'06_Pricing'!$C$3+('04_Adoption'!$C$6*'04_Adoption'!$C$5*'06_Pricing'!$C$5)*'06_Pricing'!$C$6+'05_Payroll_Activity'!$C$3*'06_Pricing'!$C$9)*(1-'06_Pricing'!$C$13) -> 3703.94 | D2: =(('04_Adoption'!$D$7*'06_Pricing'!$C$2)*'06_Pricing'!$C$3+('04_Adoption'!$D$6*'04_Adoption'!$D$5*'06_Pricing'!$C$5)*'06_Pricing'!$C$6+'05_Payroll_Activity'!$D$3*'06_Pricing'!$C$9)*(1-'06_Pricing'!$C$13) -> 9827.71 | E2: =(('04_Adoption'!$E$7*'06_Pricing'!$C$2)*'06_Pricing'!$C$3+('04_Adoption'!$E$6*'04_Adoption'!$E$5*'06_Pricing'!$C$5)*'06_Pricing'!$C$6+'05_Payroll_Activity'!$E$3*'06_Pricing'!$C$9)*(1-'06_Pricing'!$C$13) -> 19511.33 | F2: =(('04_Adoption'!$F$7*'06_Pricing'!$C$2)*'06_Pricing'!$C$3+('04_Adoption'!$F$6*'04_Adoption'!$F$5*'06_Pricing'!$C$5)*'06_Pricing'!$C$6+'05_Payroll_Activity'!$F$3*'06_Pricing'!$C$9)*(1-'06_Pricing'!$C$13) -> 30190.85 | G2: =(('04_Adoption'!$G$7*'06_Pricing'!$C$2)*'06_Pricing'!$C$3+('04_Adoption'!$G$6*'04_Adoption'!$G$5*'06_Pricing'!$C$5)*'06_Pricing'!$C$6+'05_Payroll_Activity'!$G$3*'06_Pricing'!$C$9)*(1-'06_Pricing'!$C$13) -> 39874.46
A3: Conservative | B3: Rural Bank SMS margin | C3: ='13_SMS_Variant'!$C$5 -> 8.28 | D3: ='13_SMS_Variant'!$D$5 -> 37.26 | E3: ='13_SMS_Variant'!$E$5 -> 86.94 | F3: ='13_SMS_Variant'!$F$5 -> 149.04 | G3: ='13_SMS_Variant'!$G$5 -> 198.72
A4: Conservative | B4: Rural Bank contribution before RB-002 | C4: =$C2 -> 3703.94 | D4: =$D2 -> 9827.71 | E4: =$E2 -> 19511.33 | F4: =$F2 -> 30190.85 | G4: =$G2 -> 39874.46
A5: Base | B5: Rural Bank core revenue | C5: =(('04_Adoption'!$C$13*'06_Pricing'!$C$16)*'06_Pricing'!$C$17+('04_Adoption'!$C$12*'04_Adoption'!$C$11*'06_Pricing'!$C$19)*'06_Pricing'!$C$20+'05_Payroll_Activity'!$C$6*'06_Pricing'!$C$23)*(1-'06_Pricing'!$C$27) -> 51955.68 | D5: =(('04_Adoption'!$D$13*'06_Pricing'!$C$16)*'06_Pricing'!$C$17+('04_Adoption'!$D$12*'04_Adoption'!$D$11*'06_Pricing'!$C$19)*'06_Pricing'!$C$20+'05_Payroll_Activity'!$D$6*'06_Pricing'!$C$23)*(1-'06_Pricing'!$C$27) -> 139087.87 | E5: =(('04_Adoption'!$E$13*'06_Pricing'!$C$16)*'06_Pricing'!$C$17+('04_Adoption'!$E$12*'04_Adoption'!$E$11*'06_Pricing'!$C$19)*'06_Pricing'!$C$20+'05_Payroll_Activity'!$E$6*'06_Pricing'!$C$23)*(1-'06_Pricing'!$C$27) -> 249951.74 | F5: =(('04_Adoption'!$F$13*'06_Pricing'!$C$16)*'06_Pricing'!$C$17+('04_Adoption'!$F$12*'04_Adoption'!$F$11*'06_Pricing'!$C$19)*'06_Pricing'!$C$20+'05_Payroll_Activity'!$F$6*'06_Pricing'!$C$23)*(1-'06_Pricing'!$C$27) -> 422390.98 | G5: =(('04_Adoption'!$G$13*'06_Pricing'!$C$16)*'06_Pricing'!$C$17+('04_Adoption'!$G$12*'04_Adoption'!$G$11*'06_Pricing'!$C$19)*'06_Pricing'!$C$20+'05_Payroll_Activity'!$G$6*'06_Pricing'!$C$23)*(1-'06_Pricing'!$C$27) -> 653667.84
A6: Base | B6: Rural Bank SMS margin | C6: ='13_SMS_Variant'!$C$10 -> 919.3 | D6: ='13_SMS_Variant'!$D$10 -> 3432.04 | E6: ='13_SMS_Variant'!$E$10 -> 6864.08 | F6: ='13_SMS_Variant'!$F$10 -> 12134.71 | G6: ='13_SMS_Variant'!$G$10 -> 19611.65
A7: Base | B7: Rural Bank contribution before RB-002 | C7: =$C5 -> 51955.68 | D7: =$D5 -> 139087.87 | E7: =$E5 -> 249951.74 | F7: =$F5 -> 422390.98 | G7: =$G5 -> 653667.84
A8: Accelerated | B8: Rural Bank core revenue | C8: =(('04_Adoption'!$C$19*'06_Pricing'!$C$30)*'06_Pricing'!$C$31+('04_Adoption'!$C$18*'04_Adoption'!$C$17*'06_Pricing'!$C$33)*'06_Pricing'!$C$34+'05_Payroll_Activity'!$C$9*'06_Pricing'!$C$37)*(1-'06_Pricing'!$C$41) -> 323513.31 | D8: =(('04_Adoption'!$D$19*'06_Pricing'!$C$30)*'06_Pricing'!$C$31+('04_Adoption'!$D$18*'04_Adoption'!$D$17*'06_Pricing'!$C$33)*'06_Pricing'!$C$34+'05_Payroll_Activity'!$D$9*'06_Pricing'!$C$37)*(1-'06_Pricing'!$C$41) -> 766448.18 | E8: =(('04_Adoption'!$E$19*'06_Pricing'!$C$30)*'06_Pricing'!$C$31+('04_Adoption'!$E$18*'04_Adoption'!$E$17*'06_Pricing'!$C$33)*'06_Pricing'!$C$34+'05_Payroll_Activity'!$E$9*'06_Pricing'!$C$37)*(1-'06_Pricing'!$C$41) -> 1406479.9 | F8: =(('04_Adoption'!$F$19*'06_Pricing'!$C$30)*'06_Pricing'!$C$31+('04_Adoption'!$F$18*'04_Adoption'!$F$17*'06_Pricing'!$C$33)*'06_Pricing'!$C$34+'05_Payroll_Activity'!$F$9*'06_Pricing'!$C$37)*(1-'06_Pricing'!$C$41) -> 2260973.1 | G8: =(('04_Adoption'!$G$19*'06_Pricing'!$C$30)*'06_Pricing'!$C$31+('04_Adoption'!$G$18*'04_Adoption'!$G$17*'06_Pricing'!$C$33)*'06_Pricing'!$C$34+'05_Payroll_Activity'!$G$9*'06_Pricing'!$C$37)*(1-'06_Pricing'!$C$41) -> 3162075.8
A9: Accelerated | B9: Rural Bank SMS margin | C9: ='13_SMS_Variant'!$C$15 -> 11872.16 | D9: ='13_SMS_Variant'!$D$15 -> 36181.81 | E9: ='13_SMS_Variant'!$E$15 -> 71232.94 | F9: ='13_SMS_Variant'!$F$15 -> 118721.57 | G9: ='13_SMS_Variant'!$G$15 -> 169602.25
A10: Accelerated | B10: Rural Bank contribution before RB-002 | C10: =$C8 -> 323513.31 | D10: =$D8 -> 766448.18 | E10: =$E8 -> 1406479.9 | F10: =$F8 -> 2260973.1 | G10: =$G8 -> 3162075.8

Sheet 11_ODTI_View
A1: Scenario | B1: Metric | C1: Year 1 | D1: Year 2 | E1: Year 3 | F1: Year 4 | G1: Year 5
A2: Conservative | B2: ODTI core revenue | C2: ='04_Adoption'!$C$2*'06_Pricing'!$C$11+('04_Adoption'!$C$4*'04_Adoption'!$C$5*'06_Pricing'!$C$12)/12+(('04_Adoption'!$C$7*'06_Pricing'!$C$2)*'06_Pricing'!$C$4+('04_Adoption'!$C$6*'04_Adoption'!$C$5*'06_Pricing'!$C$5)*'06_Pricing'!$C$7+'05_Payroll_Activity'!$C$3*'06_Pricing'!$C$10)*(1-'06_Pricing'!$C$13) -> 124415.9 | D2: ='04_Adoption'!$D$2*'06_Pricing'!$C$11+('04_Adoption'!$D$4*'04_Adoption'!$D$5*'06_Pricing'!$C$12)/12+(('04_Adoption'!$D$7*'06_Pricing'!$C$2)*'06_Pricing'!$C$4+('04_Adoption'!$D$6*'04_Adoption'!$D$5*'06_Pricing'!$C$5)*'06_Pricing'!$C$7+'05_Payroll_Activity'!$D$3*'06_Pricing'!$C$10)*(1-'06_Pricing'!$C$13) -> 249611.57 | E2: ='04_Adoption'!$E$2*'06_Pricing'!$C$11+('04_Adoption'!$E$4*'04_Adoption'!$E$5*'06_Pricing'!$C$12)/12+(('04_Adoption'!$E$7*'06_Pricing'!$C$2)*'06_Pricing'!$C$4+('04_Adoption'!$E$6*'04_Adoption'!$E$5*'06_Pricing'!$C$5)*'06_Pricing'!$C$7+'05_Payroll_Activity'!$E$3*'06_Pricing'!$C$10)*(1-'06_Pricing'!$C$13) -> 427296.99 | F2: ='04_Adoption'!$F$2*'06_Pricing'!$C$11+('04_Adoption'!$F$4*'04_Adoption'!$F$5*'06_Pricing'!$C$12)/12+(('04_Adoption'!$F$7*'06_Pricing'!$C$2)*'06_Pricing'!$C$4+('04_Adoption'!$F$6*'04_Adoption'!$F$5*'06_Pricing'!$C$5)*'06_Pricing'!$C$7+'05_Payroll_Activity'!$F$3*'06_Pricing'!$C$10)*(1-'06_Pricing'!$C$13) -> 584766.27 | G2: ='04_Adoption'!$G$2*'06_Pricing'!$C$11+('04_Adoption'!$G$4*'04_Adoption'!$G$5*'06_Pricing'!$C$12)/12+(('04_Adoption'!$G$7*'06_Pricing'!$C$2)*'06_Pricing'!$C$4+('04_Adoption'!$G$6*'04_Adoption'!$G$5*'06_Pricing'!$C$5)*'06_Pricing'!$C$7+'05_Payroll_Activity'!$G$3*'06_Pricing'!$C$10)*(1-'06_Pricing'!$C$13) -> 762451.7
